[2025-08-20T23:12:05.678+0000] {local_task_job_runner.py:120} INFO - ::group::Pre task execution logs
[2025-08-20T23:12:06.526+0000] {taskinstance.py:2073} INFO - Dependencies all met for dep_context=non-requeueable deps ti=<TaskInstance: user_automation.stream_data_from_api scheduled__2025-08-19T00:00:00+00:00 [queued]>
[2025-08-20T23:12:06.559+0000] {taskinstance.py:2073} INFO - Dependencies all met for dep_context=requeueable deps ti=<TaskInstance: user_automation.stream_data_from_api scheduled__2025-08-19T00:00:00+00:00 [queued]>
[2025-08-20T23:12:06.561+0000] {taskinstance.py:2303} INFO - Starting attempt 1 of 1
[2025-08-20T23:12:06.630+0000] {taskinstance.py:2327} INFO - Executing <Task(PythonOperator): stream_data_from_api> on 2025-08-19 00:00:00+00:00
[2025-08-20T23:12:06.670+0000] {standard_task_runner.py:90} INFO - Running: ['***', 'tasks', 'run', 'user_automation', 'stream_data_from_api', 'scheduled__2025-08-19T00:00:00+00:00', '--job-id', '3', '--raw', '--subdir', 'DAGS_FOLDER/kafka_stream.py', '--cfg-path', '/tmp/tmprzks3539']
[2025-08-20T23:12:06.691+0000] {standard_task_runner.py:91} INFO - Job 3: Subtask stream_data_from_api
[2025-08-20T23:12:06.727+0000] {logging_mixin.py:188} WARNING - /home/***/.local/lib/python3.12/site-packages/***/task/task_runner/standard_task_runner.py:61 DeprecationWarning: This process (pid=382) is multi-threaded, use of fork() may lead to deadlocks in the child.
[2025-08-20T23:12:06.731+0000] {standard_task_runner.py:63} INFO - Started process 388 to run task
[2025-08-20T23:12:06.948+0000] {task_command.py:426} INFO - Running <TaskInstance: user_automation.stream_data_from_api scheduled__2025-08-19T00:00:00+00:00 [running]> on host 96608d87f7e6
[2025-08-20T23:12:07.408+0000] {taskinstance.py:2644} INFO - Exporting env vars: AIRFLOW_CTX_DAG_OWNER='airscholar' AIRFLOW_CTX_DAG_ID='user_automation' AIRFLOW_CTX_TASK_ID='stream_data_from_api' AIRFLOW_CTX_EXECUTION_DATE='2025-08-19T00:00:00+00:00' AIRFLOW_CTX_TRY_NUMBER='1' AIRFLOW_CTX_DAG_RUN_ID='scheduled__2025-08-19T00:00:00+00:00'
[2025-08-20T23:12:07.414+0000] {taskinstance.py:430} INFO - ::endgroup::
[2025-08-20T23:12:14.497+0000] {conn.py:396} INFO - <BrokerConnection client_id=kafka-python-producer-1, node_id=bootstrap-0 host=broker:29092 <connecting> [IPv4 ('172.18.0.3', 29092)]>: connecting to broker:29092 [('172.18.0.3', 29092) IPv4]
[2025-08-20T23:12:14.601+0000] {conn.py:618} INFO - <BrokerConnection client_id=kafka-python-producer-1, node_id=bootstrap-0 host=broker:29092 <checking_api_versions_recv> [IPv4 ('172.18.0.3', 29092)]>: Broker version identified as 2.6
[2025-08-20T23:12:14.602+0000] {conn.py:457} INFO - <BrokerConnection client_id=kafka-python-producer-1, node_id=bootstrap-0 host=broker:29092 <connected> [IPv4 ('172.18.0.3', 29092)]>: Connection complete.
[2025-08-20T23:12:17.499+0000] {conn.py:396} INFO - <BrokerConnection client_id=kafka-python-producer-1, node_id=1 host=broker:29092 <connecting> [IPv4 ('172.18.0.3', 29092)]>: connecting to broker:29092 [('172.18.0.3', 29092) IPv4]
[2025-08-20T23:12:17.501+0000] {conn.py:457} INFO - <BrokerConnection client_id=kafka-python-producer-1, node_id=1 host=broker:29092 <connected> [IPv4 ('172.18.0.3', 29092)]>: Connection complete.
[2025-08-20T23:12:17.502+0000] {conn.py:945} INFO - <BrokerConnection client_id=kafka-python-producer-1, node_id=bootstrap-0 host=broker:29092 <connected> [IPv4 ('172.18.0.3', 29092)]>: Closing connection. 
[2025-08-20T23:12:17.654+0000] {cluster.py:316} ERROR - Topic users_created not found in cluster metadata
[2025-08-20T23:13:15.336+0000] {conn.py:945} INFO - <BrokerConnection client_id=kafka-python-producer-1, node_id=1 host=broker:29092 <connected> [IPv4 ('172.18.0.3', 29092)]>: Closing connection. 
[2025-08-20T23:13:15.358+0000] {python.py:237} INFO - Done. Returned value was: None
[2025-08-20T23:13:15.366+0000] {taskinstance.py:441} INFO - ::group::Post task execution logs
[2025-08-20T23:13:16.035+0000] {taskinstance.py:1205} INFO - Marking task as SUCCESS. dag_id=user_automation, task_id=stream_data_from_api, execution_date=20250819T000000, start_date=20250820T231206, end_date=20250820T231316
[2025-08-20T23:13:16.347+0000] {local_task_job_runner.py:240} INFO - Task exited with return code 0
[2025-08-20T23:13:17.012+0000] {taskinstance.py:3482} INFO - 0 downstream tasks scheduled from follow-on schedule check
[2025-08-20T23:13:17.021+0000] {local_task_job_runner.py:222} INFO - ::endgroup::
[2025-08-20T23:26:43.202+0000] {local_task_job_runner.py:120} INFO - ::group::Pre task execution logs
[2025-08-20T23:26:43.667+0000] {taskinstance.py:2073} INFO - Dependencies all met for dep_context=non-requeueable deps ti=<TaskInstance: user_automation.stream_data_from_api scheduled__2025-08-19T00:00:00+00:00 [queued]>
[2025-08-20T23:26:43.774+0000] {taskinstance.py:2073} INFO - Dependencies all met for dep_context=requeueable deps ti=<TaskInstance: user_automation.stream_data_from_api scheduled__2025-08-19T00:00:00+00:00 [queued]>
[2025-08-20T23:26:43.776+0000] {taskinstance.py:2303} INFO - Starting attempt 1 of 1
[2025-08-20T23:26:43.942+0000] {taskinstance.py:2327} INFO - Executing <Task(PythonOperator): stream_data_from_api> on 2025-08-19 00:00:00+00:00
[2025-08-20T23:26:43.973+0000] {standard_task_runner.py:90} INFO - Running: ['***', 'tasks', 'run', 'user_automation', 'stream_data_from_api', 'scheduled__2025-08-19T00:00:00+00:00', '--job-id', '2', '--raw', '--subdir', 'DAGS_FOLDER/kafka_stream.py', '--cfg-path', '/tmp/tmpk4m75cy9']
[2025-08-20T23:26:43.981+0000] {standard_task_runner.py:91} INFO - Job 2: Subtask stream_data_from_api
[2025-08-20T23:26:43.993+0000] {logging_mixin.py:188} WARNING - /home/***/.local/lib/python3.12/site-packages/***/task/task_runner/standard_task_runner.py:61 DeprecationWarning: This process (pid=207) is multi-threaded, use of fork() may lead to deadlocks in the child.
[2025-08-20T23:26:43.996+0000] {standard_task_runner.py:63} INFO - Started process 208 to run task
[2025-08-20T23:26:44.301+0000] {task_command.py:426} INFO - Running <TaskInstance: user_automation.stream_data_from_api scheduled__2025-08-19T00:00:00+00:00 [running]> on host 842391f52549
[2025-08-20T23:26:45.310+0000] {taskinstance.py:2644} INFO - Exporting env vars: AIRFLOW_CTX_DAG_OWNER='airscholar' AIRFLOW_CTX_DAG_ID='user_automation' AIRFLOW_CTX_TASK_ID='stream_data_from_api' AIRFLOW_CTX_EXECUTION_DATE='2025-08-19T00:00:00+00:00' AIRFLOW_CTX_TRY_NUMBER='1' AIRFLOW_CTX_DAG_RUN_ID='scheduled__2025-08-19T00:00:00+00:00'
[2025-08-20T23:26:45.316+0000] {taskinstance.py:430} INFO - ::endgroup::
[2025-08-20T23:26:49.105+0000] {conn.py:396} INFO - <BrokerConnection client_id=kafka-python-producer-1, node_id=bootstrap-0 host=broker:29092 <connecting> [IPv4 ('172.18.0.3', 29092)]>: connecting to broker:29092 [('172.18.0.3', 29092) IPv4]
[2025-08-20T23:26:49.258+0000] {conn.py:618} INFO - <BrokerConnection client_id=kafka-python-producer-1, node_id=bootstrap-0 host=broker:29092 <checking_api_versions_recv> [IPv4 ('172.18.0.3', 29092)]>: Broker version identified as 2.6
[2025-08-20T23:26:49.268+0000] {conn.py:457} INFO - <BrokerConnection client_id=kafka-python-producer-1, node_id=bootstrap-0 host=broker:29092 <connected> [IPv4 ('172.18.0.3', 29092)]>: Connection complete.
[2025-08-20T23:26:51.655+0000] {conn.py:396} INFO - <BrokerConnection client_id=kafka-python-producer-1, node_id=1 host=broker:29092 <connecting> [IPv4 ('172.18.0.3', 29092)]>: connecting to broker:29092 [('172.18.0.3', 29092) IPv4]
[2025-08-20T23:26:51.674+0000] {conn.py:457} INFO - <BrokerConnection client_id=kafka-python-producer-1, node_id=1 host=broker:29092 <connected> [IPv4 ('172.18.0.3', 29092)]>: Connection complete.
[2025-08-20T23:26:51.675+0000] {conn.py:945} INFO - <BrokerConnection client_id=kafka-python-producer-1, node_id=bootstrap-0 host=broker:29092 <connected> [IPv4 ('172.18.0.3', 29092)]>: Closing connection. 
[2025-08-20T23:26:51.697+0000] {cluster.py:316} ERROR - Topic users_created not found in cluster metadata
[2025-08-20T23:27:05.620+0000] {kafka_stream.py:57} ERROR - An error occured: HTTPSConnectionPool(host='randomuser.me', port=443): Max retries exceeded with url: /api/ (Caused by NewConnectionError('<urllib3.connection.HTTPSConnection object at 0x7f56292a4f50>: Failed to establish a new connection: [Errno -3] Temporary failure in name resolution'))
[2025-08-20T23:27:15.729+0000] {kafka_stream.py:57} ERROR - An error occured: HTTPSConnectionPool(host='randomuser.me', port=443): Max retries exceeded with url: /api/ (Caused by NewConnectionError('<urllib3.connection.HTTPSConnection object at 0x7f56292a5790>: Failed to establish a new connection: [Errno -3] Temporary failure in name resolution'))
[2025-08-20T23:27:25.732+0000] {kafka_stream.py:57} ERROR - An error occured: HTTPSConnectionPool(host='randomuser.me', port=443): Max retries exceeded with url: /api/ (Caused by NewConnectionError('<urllib3.connection.HTTPSConnection object at 0x7f56292a5790>: Failed to establish a new connection: [Errno -3] Temporary failure in name resolution'))
[2025-08-20T23:27:32.842+0000] {job.py:218} ERROR - Job heartbeat got an exception
Traceback (most recent call last):
  File "/home/airflow/.local/lib/python3.12/site-packages/sqlalchemy/engine/base.py", line 3371, in _wrap_pool_connect
    return fn()
           ^^^^
  File "/home/airflow/.local/lib/python3.12/site-packages/sqlalchemy/pool/base.py", line 327, in connect
    return _ConnectionFairy._checkout(self)
           ^^^^^^^^^^^^^^^^^^^^^^^^^^^^^^^^
  File "/home/airflow/.local/lib/python3.12/site-packages/sqlalchemy/pool/base.py", line 894, in _checkout
    fairy = _ConnectionRecord.checkout(pool)
            ^^^^^^^^^^^^^^^^^^^^^^^^^^^^^^^^
  File "/home/airflow/.local/lib/python3.12/site-packages/sqlalchemy/pool/base.py", line 493, in checkout
    rec = pool._do_get()
          ^^^^^^^^^^^^^^
  File "/home/airflow/.local/lib/python3.12/site-packages/sqlalchemy/pool/impl.py", line 256, in _do_get
    return self._create_connection()
           ^^^^^^^^^^^^^^^^^^^^^^^^^
  File "/home/airflow/.local/lib/python3.12/site-packages/sqlalchemy/pool/base.py", line 273, in _create_connection
    return _ConnectionRecord(self)
           ^^^^^^^^^^^^^^^^^^^^^^^
  File "/home/airflow/.local/lib/python3.12/site-packages/sqlalchemy/pool/base.py", line 388, in __init__
    self.__connect()
  File "/home/airflow/.local/lib/python3.12/site-packages/sqlalchemy/pool/base.py", line 690, in __connect
    with util.safe_reraise():
  File "/home/airflow/.local/lib/python3.12/site-packages/sqlalchemy/util/langhelpers.py", line 70, in __exit__
    compat.raise_(
  File "/home/airflow/.local/lib/python3.12/site-packages/sqlalchemy/util/compat.py", line 211, in raise_
    raise exception
  File "/home/airflow/.local/lib/python3.12/site-packages/sqlalchemy/pool/base.py", line 686, in __connect
    self.dbapi_connection = connection = pool._invoke_creator(self)
                                         ^^^^^^^^^^^^^^^^^^^^^^^^^^
  File "/home/airflow/.local/lib/python3.12/site-packages/sqlalchemy/engine/create.py", line 574, in connect
    return dialect.connect(*cargs, **cparams)
           ^^^^^^^^^^^^^^^^^^^^^^^^^^^^^^^^^^
  File "/home/airflow/.local/lib/python3.12/site-packages/sqlalchemy/engine/default.py", line 598, in connect
    return self.dbapi.connect(*cargs, **cparams)
           ^^^^^^^^^^^^^^^^^^^^^^^^^^^^^^^^^^^^^
  File "/home/airflow/.local/lib/python3.12/site-packages/psycopg2/__init__.py", line 122, in connect
    conn = _connect(dsn, connection_factory=connection_factory, **kwasync)
           ^^^^^^^^^^^^^^^^^^^^^^^^^^^^^^^^^^^^^^^^^^^^^^^^^^^^^^^^^^^^^^^
psycopg2.OperationalError: could not translate host name "postgres" to address: Temporary failure in name resolution


The above exception was the direct cause of the following exception:

Traceback (most recent call last):
  File "/home/airflow/.local/lib/python3.12/site-packages/airflow/jobs/job.py", line 192, in heartbeat
    self._merge_from(Job._fetch_from_db(self, session))
                     ^^^^^^^^^^^^^^^^^^^^^^^^^^^^^^^^^
  File "/home/airflow/.local/lib/python3.12/site-packages/airflow/api_internal/internal_api_call.py", line 115, in wrapper
    return func(*args, **kwargs)
           ^^^^^^^^^^^^^^^^^^^^^
  File "/home/airflow/.local/lib/python3.12/site-packages/airflow/utils/session.py", line 76, in wrapper
    return func(*args, **kwargs)
           ^^^^^^^^^^^^^^^^^^^^^
  File "/home/airflow/.local/lib/python3.12/site-packages/airflow/utils/retries.py", line 89, in wrapped_function
    for attempt in run_with_db_retries(max_retries=retries, logger=logger, **retry_kwargs):
  File "/home/airflow/.local/lib/python3.12/site-packages/tenacity/__init__.py", line 347, in __iter__
    do = self.iter(retry_state=retry_state)
         ^^^^^^^^^^^^^^^^^^^^^^^^^^^^^^^^^^
  File "/home/airflow/.local/lib/python3.12/site-packages/tenacity/__init__.py", line 325, in iter
    raise retry_exc.reraise()
          ^^^^^^^^^^^^^^^^^^^
  File "/home/airflow/.local/lib/python3.12/site-packages/tenacity/__init__.py", line 158, in reraise
    raise self.last_attempt.result()
          ^^^^^^^^^^^^^^^^^^^^^^^^^^
  File "/usr/local/lib/python3.12/concurrent/futures/_base.py", line 449, in result
    return self.__get_result()
           ^^^^^^^^^^^^^^^^^^^
  File "/usr/local/lib/python3.12/concurrent/futures/_base.py", line 401, in __get_result
    raise self._exception
  File "/home/airflow/.local/lib/python3.12/site-packages/airflow/utils/retries.py", line 98, in wrapped_function
    return func(*args, **kwargs)
           ^^^^^^^^^^^^^^^^^^^^^
  File "/home/airflow/.local/lib/python3.12/site-packages/airflow/jobs/job.py", line 316, in _fetch_from_db
    session.merge(job)
  File "/home/airflow/.local/lib/python3.12/site-packages/sqlalchemy/orm/session.py", line 3056, in merge
    return self._merge(
           ^^^^^^^^^^^^
  File "/home/airflow/.local/lib/python3.12/site-packages/sqlalchemy/orm/session.py", line 3136, in _merge
    merged = self.get(
             ^^^^^^^^^
  File "/home/airflow/.local/lib/python3.12/site-packages/sqlalchemy/orm/session.py", line 2853, in get
    return self._get_impl(
           ^^^^^^^^^^^^^^^
  File "/home/airflow/.local/lib/python3.12/site-packages/sqlalchemy/orm/session.py", line 2975, in _get_impl
    return db_load_fn(
           ^^^^^^^^^^^
  File "/home/airflow/.local/lib/python3.12/site-packages/sqlalchemy/orm/loading.py", line 530, in load_on_pk_identity
    session.execute(
  File "/home/airflow/.local/lib/python3.12/site-packages/sqlalchemy/orm/session.py", line 1716, in execute
    conn = self._connection_for_bind(bind)
           ^^^^^^^^^^^^^^^^^^^^^^^^^^^^^^^
  File "/home/airflow/.local/lib/python3.12/site-packages/sqlalchemy/orm/session.py", line 1555, in _connection_for_bind
    return self._transaction._connection_for_bind(
           ^^^^^^^^^^^^^^^^^^^^^^^^^^^^^^^^^^^^^^^
  File "/home/airflow/.local/lib/python3.12/site-packages/sqlalchemy/orm/session.py", line 750, in _connection_for_bind
    conn = bind.connect()
           ^^^^^^^^^^^^^^
  File "/home/airflow/.local/lib/python3.12/site-packages/sqlalchemy/future/engine.py", line 412, in connect
    return super(Engine, self).connect()
           ^^^^^^^^^^^^^^^^^^^^^^^^^^^^^
  File "/home/airflow/.local/lib/python3.12/site-packages/sqlalchemy/engine/base.py", line 3325, in connect
    return self._connection_cls(self, close_with_result=close_with_result)
           ^^^^^^^^^^^^^^^^^^^^^^^^^^^^^^^^^^^^^^^^^^^^^^^^^^^^^^^^^^^^^^^
  File "/home/airflow/.local/lib/python3.12/site-packages/sqlalchemy/engine/base.py", line 96, in __init__
    else engine.raw_connection()
         ^^^^^^^^^^^^^^^^^^^^^^^
  File "/home/airflow/.local/lib/python3.12/site-packages/sqlalchemy/engine/base.py", line 3404, in raw_connection
    return self._wrap_pool_connect(self.pool.connect, _connection)
           ^^^^^^^^^^^^^^^^^^^^^^^^^^^^^^^^^^^^^^^^^^^^^^^^^^^^^^^
  File "/home/airflow/.local/lib/python3.12/site-packages/sqlalchemy/engine/base.py", line 3374, in _wrap_pool_connect
    Connection._handle_dbapi_exception_noconnection(
  File "/home/airflow/.local/lib/python3.12/site-packages/sqlalchemy/engine/base.py", line 2208, in _handle_dbapi_exception_noconnection
    util.raise_(
  File "/home/airflow/.local/lib/python3.12/site-packages/sqlalchemy/util/compat.py", line 211, in raise_
    raise exception
  File "/home/airflow/.local/lib/python3.12/site-packages/sqlalchemy/engine/base.py", line 3371, in _wrap_pool_connect
    return fn()
           ^^^^
  File "/home/airflow/.local/lib/python3.12/site-packages/sqlalchemy/pool/base.py", line 327, in connect
    return _ConnectionFairy._checkout(self)
           ^^^^^^^^^^^^^^^^^^^^^^^^^^^^^^^^
  File "/home/airflow/.local/lib/python3.12/site-packages/sqlalchemy/pool/base.py", line 894, in _checkout
    fairy = _ConnectionRecord.checkout(pool)
            ^^^^^^^^^^^^^^^^^^^^^^^^^^^^^^^^
  File "/home/airflow/.local/lib/python3.12/site-packages/sqlalchemy/pool/base.py", line 493, in checkout
    rec = pool._do_get()
          ^^^^^^^^^^^^^^
  File "/home/airflow/.local/lib/python3.12/site-packages/sqlalchemy/pool/impl.py", line 256, in _do_get
    return self._create_connection()
           ^^^^^^^^^^^^^^^^^^^^^^^^^
  File "/home/airflow/.local/lib/python3.12/site-packages/sqlalchemy/pool/base.py", line 273, in _create_connection
    return _ConnectionRecord(self)
           ^^^^^^^^^^^^^^^^^^^^^^^
  File "/home/airflow/.local/lib/python3.12/site-packages/sqlalchemy/pool/base.py", line 388, in __init__
    self.__connect()
  File "/home/airflow/.local/lib/python3.12/site-packages/sqlalchemy/pool/base.py", line 690, in __connect
    with util.safe_reraise():
  File "/home/airflow/.local/lib/python3.12/site-packages/sqlalchemy/util/langhelpers.py", line 70, in __exit__
    compat.raise_(
  File "/home/airflow/.local/lib/python3.12/site-packages/sqlalchemy/util/compat.py", line 211, in raise_
    raise exception
  File "/home/airflow/.local/lib/python3.12/site-packages/sqlalchemy/pool/base.py", line 686, in __connect
    self.dbapi_connection = connection = pool._invoke_creator(self)
                                         ^^^^^^^^^^^^^^^^^^^^^^^^^^
  File "/home/airflow/.local/lib/python3.12/site-packages/sqlalchemy/engine/create.py", line 574, in connect
    return dialect.connect(*cargs, **cparams)
           ^^^^^^^^^^^^^^^^^^^^^^^^^^^^^^^^^^
  File "/home/airflow/.local/lib/python3.12/site-packages/sqlalchemy/engine/default.py", line 598, in connect
    return self.dbapi.connect(*cargs, **cparams)
           ^^^^^^^^^^^^^^^^^^^^^^^^^^^^^^^^^^^^^
  File "/home/airflow/.local/lib/python3.12/site-packages/psycopg2/__init__.py", line 122, in connect
    conn = _connect(dsn, connection_factory=connection_factory, **kwasync)
           ^^^^^^^^^^^^^^^^^^^^^^^^^^^^^^^^^^^^^^^^^^^^^^^^^^^^^^^^^^^^^^^
sqlalchemy.exc.OperationalError: (psycopg2.OperationalError) could not translate host name "postgres" to address: Temporary failure in name resolution

(Background on this error at: https://sqlalche.me/e/14/e3q8)
[2025-08-20T23:27:32.980+0000] {job.py:226} ERROR - Job heartbeat failed with error. Scheduler is in unhealthy state
[2025-08-20T23:27:35.803+0000] {kafka_stream.py:57} ERROR - An error occured: HTTPSConnectionPool(host='randomuser.me', port=443): Max retries exceeded with url: /api/ (Caused by NewConnectionError('<urllib3.connection.HTTPSConnection object at 0x7f56292a6990>: Failed to establish a new connection: [Errno -3] Temporary failure in name resolution'))
[2025-08-20T23:27:45.880+0000] {kafka_stream.py:57} ERROR - An error occured: HTTPSConnectionPool(host='randomuser.me', port=443): Max retries exceeded with url: /api/ (Caused by NewConnectionError('<urllib3.connection.HTTPSConnection object at 0x7f56292a5790>: Failed to establish a new connection: [Errno -3] Temporary failure in name resolution'))
[2025-08-20T23:27:51.309+0000] {conn.py:945} INFO - <BrokerConnection client_id=kafka-python-producer-1, node_id=1 host=broker:29092 <connected> [IPv4 ('172.18.0.3', 29092)]>: Closing connection. 
[2025-08-20T23:27:51.326+0000] {python.py:237} INFO - Done. Returned value was: None
[2025-08-20T23:27:51.328+0000] {taskinstance.py:441} INFO - ::group::Post task execution logs
[2025-08-20T23:27:51.823+0000] {taskinstance.py:1205} INFO - Marking task as SUCCESS. dag_id=user_automation, task_id=stream_data_from_api, execution_date=20250819T000000, start_date=20250820T232643, end_date=20250820T232751
[2025-08-20T23:27:51.996+0000] {local_task_job_runner.py:240} INFO - Task exited with return code 0
[2025-08-20T23:27:52.182+0000] {taskinstance.py:3482} INFO - 0 downstream tasks scheduled from follow-on schedule check
[2025-08-20T23:27:52.189+0000] {local_task_job_runner.py:222} INFO - ::endgroup::
